<mujocoinclude>
    <body name="R_link_base" childclass="lite6">
      <inertial pos="-0.00829545 3.26357e-05 0.0631195" mass="1.65394" diaginertia="0 0 0"/>
      <geom class="6-visual" mesh="6-link_base"/>
      <geom name="R_link_base_c" class="6-collision" mesh="6-link_base_c"/>
      <body name="R_link1" pos="0 0 0.2435">
        <inertial pos="-0.00036 0.04195 -0.0025" quat="0.608059 0.792349 -0.0438707 0.0228718" mass="1.411"
          diaginertia="0.00145276 0.00135275 0.000853355"/>
        <joint name="R_joint1" range="-6.28319 6.28319"/>
        <geom class="6-visual" mesh="6-link1"/>
        <geom name="R_link1_c" class="6-collision" mesh="6-link1_c"/>
        <body name="R_link2" quat="-1 1 1 1">
          <inertial pos="0.179 0 0.0584" quat="0.417561 0.571619 0.569585 0.417693" mass="1.34"
            diaginertia="0.00560971 0.0052152 0.00122018"/>
          <joint name="R_joint2" range="-2.61799 2.61799"/>
          <geom class="6-visual" mesh="6-link2"/>
          <geom name="R_link2_c" class="6-collision" mesh="6-link2_c"/>
          <body name="R_link3" pos="0.2002 0 0" quat="-2.59734e-06 -0.707105 -0.707108 -2.59735e-06">
            <inertial pos="0.072 -0.0357 -0.001" quat="0.128259 0.662963 -0.167256 0.71837" mass="0.953"
              diaginertia="0.0018521 0.00175546 0.000703807"/>
            <joint name="R_joint3" range="-0.061087 5.23599"/>
            <geom class="6-visual" mesh="6-link3"/>
            <geom name="R_link3_c" class="6-collision" mesh="6-link3_c"/>
            <body name="R_link4" pos="0.087 -0.22761 0" quat="0.707105 0.707108 0 0">
              <inertial pos="-0.002 -0.0285 -0.0813" quat="0.975248 0.22109 0.00203498 -0.00262178" mass="1.284"
                diaginertia="0.00370503 0.00349091 0.00109586"/>
              <joint name="R_joint4" range="-6.28319 6.28319"/>
              <geom class="6-visual" mesh="6-link4"/>
              <geom name="R_link4_c" class="6-collision" mesh="6-link4_c"/>
              <body name="R_link5" quat="1 1 0 0">
                <inertial pos="0 0.01 0.0019" quat="0.71423 0.696388 -0.0531933 0.0456997" mass="0.804"
                  diaginertia="0.000567553 0.000529266 0.000507681"/>
                <joint name="R_joint5" range="-2.1642 2.1642"/>
                <geom class="6-visual" mesh="6-link5"/>
                <geom name="R_link5_c" class="6-collision" mesh="6-link5_c"/>
                <body name="R_link6" pos="0 0.0625 0" quat="1 -1 0 0">
                  <inertial pos="0 -0.00194 -0.0102" quat="-0.0376023 0.704057 0.0446838 0.707738" mass="0.13"
                    diaginertia="0.000148148 8.57757e-05 7.71412e-05"/>
                  <joint name="R_joint6" range="-6.28319 6.28319"/>
                  <geom class="6-visual" mesh="6-link6" material="silver"/>
                  <geom name="R_link6_c" class="6-collision" mesh="6-link6_c"/>
                  <site name="attachment_site"/>
                  <body name="R_gripper_body" pos="0 0 0" quat="1 0 0 0">
                    <inertial pos="0.0 0.0 0.026" quat="1 0 0 0" mass="0.26"
                      diaginertia="0.00016117 0.000118 0.00014455" />
                    <geom name="R_gripper_lite_body" class="visual" mesh="gripper_lite_body" material="white"/>
                    <geom name="R_gripper_lite_body_c" class="collision" mesh="gripper_lite_body_c"/>
                    <body name="R_gripper_left_finger" pos="0 0 0.054" quat="1 0 0 0">
                      <inertial pos="0.0 -0.005 0.01" quat="1 0 0 0" mass="0.024"
                        diaginertia="1.961e-6 2.274e-6 1.238e-6" />
                      <geom name="R_gripper_left_finger" mesh="gripper_lite_left_finger_narrow" material="black" condim="4" solimp="2 1 0.01" solref="0.01 1" friction="1 0.005 0.0001"/>
                      <joint name="R_gripper_left_finger" pos="0 0 0" axis="0 1 0" type="slide" limited="true" range="-0.0081 -1e-5" frictionloss="1" />
                    </body>
                    <body name="R_gripper_right_finger" pos="0 0 0.054" quat="1 0 0 0">
                      <inertial pos="0.0 0.005 0.01" quat="1 0 0 0" mass="0.024"
                        diaginertia="1.961e-6 2.274e-6 1.238e-6" />
                      <geom name="R_gripper_right_finger" mesh="gripper_lite_right_finger_narrow" material="black" condim="4" solimp="2 1 0.01" solref="0.01 1" friction="1 0.005 0.0001"/>
                      <joint name="R_gripper_right_finger" pos="0 0 0" axis="0 1 0" type="slide" limited="true" range="1e-5 0.0081" frictionloss="1" />
                    </body>
                    <!-- End effector reference point is in the middle of the tips of the R_grippers -->
                    <site name="end_effector" pos="0 0 0.0811"/>
                </body>
              </body>
            </body>
          </body>
        </body>
      </body>
    </body>
  </body>
</mujocoinclude>
